Workbook
Name Cdvdt: 'Calculation Sheet'!$D$44
Name Cdvdt_cal1: 'Calculation Sheet'!$D$41
Name Cdvdt_cal2: 'Calculation Sheet'!$D$42
Name Cout: 'Calculation Sheet'!$D$10
Name Gain_dvdt: 'Calculation Sheet'!$D$93
Name Gain_IMON: 'Calculation Sheet'!$D$97
Name I_dvdt: 'Calculation Sheet'!$D$92
Name Icharge: 'Calculation Sheet'!$D$46
Name Icharge_req: 'Calculation Sheet'!#REF!
Name Ilimit: 'Calculation Sheet'!$D$15
Name Ilimit_final: 'Calculation Sheet'!$D$34
Name Imax: 'Calculation Sheet'!$D$13
Name INRUSH: 'Calculation Sheet'!$D$14
Name OVPref: 'Calculation Sheet'!$D$91
Name OVset: 'Calculation Sheet'!$D$9
Name PGSET: 'Calculation Sheet'!$D$59
Name PGTHF: 'Calculation Sheet'!$D$96
Name PGTHR: 'Calculation Sheet'!$D$95
Name PLIM: 'Calculation Sheet'!$D$66
Name Pload: 'Calculation Sheet'!$D$113
Name Rdson_125deg: 'Calculation Sheet'!$D$86
Name Rdson_25deg: 'Calculation Sheet'!$D$84
Name Rdson_85deg: 'Calculation Sheet'!$D$85
Name Rilim: 'Calculation Sheet'!$D$33
Name RIMON_sel: 'Calculation Sheet'!$D$74
Name RIN: 'Calculation Sheet'!$D$24
Name Rlimit: 'Calculation Sheet'!$D$33
Name RLstart: 'Calculation Sheet'!$D$12
Name ROVP: 'Calculation Sheet'!$D$22
Name RUVLO: 'Calculation Sheet'!$D$23
Name Ta: 'Calculation Sheet'!$D$11
Name Tdvdt: 'Calculation Sheet'!$D$45
Name Tdvdt_default: 'Calculation Sheet'!$D$94
Name Tdvdt_req: 'Calculation Sheet'!$D$40
Name UVLOhys: 'Calculation Sheet'!$D$90
Name UVLOref: 'Calculation Sheet'!$D$89
Name UVset: 'Calculation Sheet'!$D$8
Name Vinmax: 'Calculation Sheet'!$D$6
Name VINmin: 'Calculation Sheet'!$D$5
Name VINnom: 'Calculation Sheet'!$D$7

Sheet Instructions
A1: Instructions for using the TPS2663x/TPS1663x Design Calculator
A2: Design Inputs • Enter the design inputs for operating input voltage, under voltage, overvoltage set points, output capacitance, ambient temperature, load at start-up, maximum continuous load current, and permissible inrush current at start up for charging output capacitance in cells D5 to D14 in Calculation Sheet. • Select the current limit for device (ILimit) at-least 5% more than (Imax + IINRUSH_Permissible) in Cell D15 in Calculation Sheet. UVLO, OVP Calculations • Enter the value of resistor (R3) between UVLO and OVP pins in Cell D18 in Calculation in Calculation Sheet • Design Calculator provides the calculated value of R2, R3 • Select the value of R1, R2 and R3 resistors in cells D22 to D24 close to the calculated values. • Design calculator provides the final under voltage, overvoltage and power fail set points based on selected values of R1 to R3 in cells D22 to D24. • Verify the value of current through resistors R1 to R3. The color of cell D28 changes based on value of current. If Current < 2uA, the cell turns RED and value of R3 needs to be reduced. Current Limit Calculations • Design Calculator provides the calculated value of resistor for ILIM • Select the value of resistor for ILIM close to the calculated value. • Design Calculator provides the value of ILIM based on selected value if ILIM resistor in Cell D34. dVdT resistor and Output ramp time Calculations • Design Calculator provides the value of tdvdt with permissible inrush current . • Design Calculator provides calculated value of Cdvdt for permissible inrush current in Cell D41 • Verify that sum of final inrush current and load current during startup is less than final ILimit. If sum of final inrush current and load current during startup is more than ILimit, Cell D47 turns RED and value of Permissible inrush current in Cell D14 needs to be increased. Power Dissipation and thermal regulation at start up. • Design calculator provides the calculated values of power dissipation at start-up • Design calculator checks the power dissipated with thermal shutdown limit data in the adjacent sheet. • If the device goes in to thermal regulation at startup, the device will reduce the current and regulate the junction temperature to TJ_reg value for a maximum duration of t(Treg_timeout). Refer to Max_Cap_charging sheet for maximum value of capacitance charged by device in thermal regulation at start-up. • If thermal regulation is not desirable at start up, reduce the value of permissible inrush current in Cell D14 Calculations for Power Good. • Enter the value of power good set point in Cell D59. This value needs to be greater than or equal to UVLO set point of the DC – DC converter or linear regulator connected on the output of the device. • Enter the value of R4 resistor (> 100k) • Design calculator provides the value of R5 and the voltage at which Power good will de-assert (go low). • Verify the value of current through R4, R5 resistor. If current is less than 2uA, cell D63 turns RED and value of R4 needs to be reduced. Calculations for Power Limit (PLIM). • Enter the desired value of power limit based output power. • Design calculator provides the value of PLIM resistor. • Verify the power limit with maximum power at nominal input voltage [=VIN(nom) x ILimit]. If power limit is more than maximum power at nominal input voltage, Cell D66 turns RED. To make power limiting effective over current limiting, it is recommend to reduce the power limit. Calculations for Current Monitor output • Enter the value for maximum IMON pin voltage based on input range of the ADC connected on IMON pin • Design calculator provides the calculated value of resistor for IMON pin • Select the value of resistor on IMON pin in cell D74 close to calculated value. • Verify that value of voltage is less than 4V. if value is more than 4V, Cell D73 turns RED and then reduce the resistor value in Cell D74. Internal FET parameters and References • Do not change the values and parameters in Internal FET parameters and References. Selection of External FET for reverses current blocking (RCB) and Reverse polarity protection (RPP). • Design calculator provides specifications of external FET for RCB and RPP. Selection of Pull Down switche for External FET. • Design calculator provides specifications for pull down switch for external FET. Selection of components for IEC61000-4-5 (Surge) • Enter the output load power • Design calculator provides the recommended value of COUT for Class-A operation based on output load power, nominal input voltage and power good set point.

Sheet Typical_App_Circuit

Sheet Calculation Sheet
B1: TPS2663x and TPS1663x Design Calculator Tool
B2: Constants Cells | C2: Input / Select Cells | D2: Calculation Cells | E2: Verification Cells
C3: Calculated, but can be over-ridden by the user. Note: Once cells are over-ridden, new calculation sheet should be used for the next design
B4: Design Inputs | C4: Description | D4: Value | E4: Units | F4: Tolerance
B5: VIN (min) | C5: Minimum Operating Input Voltage | D5: 8 | E5: V
B6: VIN (max) | C6: Maximum Operating Input Voltage | D6: 36 | E6: V
B7: VIN (nom) | C7: Nominal operating Input voltage | D7: 24 | E7: V
B8: UVset | C8: Undervoltage Lockout Set point | D8: 7.8 | E8: V
B9: OVset | C9: Over Voltage Cut-Off Set point | D9: 37 | E9: V
B10: Cout | C10: Load Capacitance | D10: 1000 | E10: µF | F10: 0.1
B11: TA (max) | C11: Maximum Ambient Temperature | D11: TA = 25C | E11: °C
B12: RLstart | C12: Load during start-up (Assumed to be resistive) | D12: 50 | E12: Ω
B13: Imax | C13: Maximum continuous load current | D13: 5.2 | E13: A
B14: IINRUSH_permissible | C14: Permissible inrush current from power supply or system for charging Cout on Start-up | D14: 0.4 | E14: A
B15: ILimit | C15: Current Limit, 5% higher than [Imax + IINRUSH_permissible ] | D15: =1.05*(D13+D14) -> 5.88 | E15: A
B17: UVLO, OVP Calculations | C17: OVP Calculations are only for TPS26630,TPS26631 and TPS16630.
B18: R3_sel | C18: Select a value of resistor between OVP and GND pins [1k to 249k] | D18: 15 | E18: kΩ | F18: 0.01 | M18: =IF(N18>976,976,IF(N18<100, 100, N18)) -> 150 | N18: =IF(D18<=9.88, D18*100, IF(AND(D18>9.88, D18<=98.8),D18*10,IF(AND(D18>98.8, D18<=988), D18, IF(AND(D18>988, D18<=9880), D18/10, IF(AND(D18>9880, D18<=98800), D18/100))))) -> 150
B19: R2_cal | C19: Calculated value of Resistor between UVLO and OVP pins | D19: =D18*((UVLOref*OVset/(UVset*OVPref))-1) -> 56.153846 | E19: kΩ | J19: =D27 -> 7.2723034 | K19: Power Fail (VIN Falling) | M19: =IF(N19>976,976,IF(N19<100, 100, N19)) -> 561.53846 | N19: =IF(D19<=9.88, D19*100, IF(AND(D19>9.88, D19<=98.8),D19*10,IF(AND(D19>98.8, D19<=988), D19, IF(AND(D19>988, D19<=9880), D19/10, IF(AND(D19>9880, D19<=98800), D19/100))))) -> 561.53846
B20: R1_cal | C20: Verify value of Resistor at IN_SYS and UVLO pins [> 300k] | D20: =D18*(OVset/OVPref)*(1-(UVLOref/UVset)) -> 391.34615 | E20: kΩ | J20: =D25 -> 7.6550562 | K20: UVLO (VIN Rising) | M20: =IF(N20>976,976,IF(N20<100, 100, N20)) -> 391.34615 | N20: =IF(D20<=9.88, D20*100, IF(AND(D20>9.88, D20<=98.8),D20*10,IF(AND(D20>98.8, D20<=988), D20, IF(AND(D20>988, D20<=9880), D20/10, IF(AND(D20>9880, D20<=98800), D20/100))))) -> 391.34615
B21: SELECT THE CLOSEST POSSIBLE RESISTANCE VALUE FOR R1, R2, R3 | J21: =D26 -> 36.336 | K21: OVP (VIN Rising)
B22: R3_sel | C22: Selected closest possible value for R3 resistor | D22: =G22 -> 15 | E22: kΩ | F22: =F18 -> 0.01 | G22: =M22/POWER(10,ROUND(LOG10(M18/D18),1)) -> 15 | M22: =INDEX('Res EIA Tables'!E$5:E$196,MATCH(M18,'Res EIA Tables'!E$5:E$196)) -> 150 | N22: =POWER(10,ROUND(LOG10(M18/D18),1)) -> 10
B23: R2_sel | C23: Selected closest possible value for R2 resistor | D23: =G23 -> 56.2 | E23: kΩ | F23: =F18 -> 0.01 | G23: =M23/POWER(10,ROUND(LOG10(M19/D19),1)) -> 56.2 | M23: =INDEX('Res EIA Tables'!E$5:E$196,2+MATCH(M19,'Res EIA Tables'!E$5:E$196)) -> 562 | N23: =POWER(10,ROUND(LOG10(M19/D19),1)) -> 10
B24: R1_sel | C24: Selected closest possible value for R1 resistor | D24: =G24 -> 383 | E24: kΩ | F24: =F18 -> 0.01 | G24: =M24/POWER(10,ROUND(LOG10(M20/D20),1)) -> 383 | M24: =INDEX('Res EIA Tables'!E$5:E$196,MATCH(M20,'Res EIA Tables'!E$5:E$196)) -> 383 | N24: =POWER(10,ROUND(LOG10(M20/D20),1)) -> 1
B25: UV_Final | C25: =C8 -> Undervoltage Lockout Set point | D25: =UVLOref*((ROVP+RUVLO+RIN)/(ROVP+RUVLO)) -> 7.6550562 | E25: V | F25: =SQRT(F89^2+F22^2+F23^2+F24^2) -> 0.026457513
B26: OV_Final | C26: =C9 -> Over Voltage Cut-Off Set point | D26: =OVPref*((ROVP+RUVLO+RIN)/ROVP) -> 36.336 | E26: V | F26: =SQRT(F91^2+F22^2+F23^2+F24^2) -> 0.026457513
B27: Power Fail Detection | C27: Power Fail Detection Set Point | D27: =(UVLOref-UVLOhys)*((ROVP+RUVLO+RIN)/(ROVP+RUVLO)) -> 7.2723034 | E27: V | F27: =F25 -> 0.026457513
B28: I_R123 | C28: Verify minimum Current in R1, R2, R3 Branch at Input voltage of Uvset [> 2uA] | D28: =UVset*1000/(ROVP+RUVLO+RIN) -> 17.173052 | E28: uA
B30: Current Limit Calculations
B31: RLIM_cal | C31: Calculated current limit resistor value | D31: =MAX((18/(Ilimit)),3) -> 3.0612245 | E31: kΩ | F31: 0.01 | J31: =Icharge -> 0.41111111 | K31: Inrush Charging Current | M31: =IF(D31<10, D31*100, IF(AND(D31>=10, D31<100),D31*10,IF(AND(D31>=100, D31<1000), D31, IF(D31>=1000, D31/10)))) -> 306.12245
B32: SELECT THE CLOSEST POSSIBLE RESISTANCE VALUE FOR RLIM | J32: =Ilimit_final -> 5.9800664 | K32: Overload Current Limit
B33: RLIM | C33: Selected closest possible value for RLIM resistor | D33: =G33 -> 3.01 | E33: kΩ | F33: =F31 -> 0.01 | G33: =M33*D31/M31 -> 3.01 | J33: =#REF! -> #REF! | K33: Fastrip Current Limit | M33: =INDEX('Res EIA Tables'!E$5:E$196,MATCH(M31,'Res EIA Tables'!E$5:E$196)) -> 301
B34: ILimit_Final | C34: Final Current Limit Set Point | D34: =18/Rilim -> 5.9800664 | E34: A | F34: =SQRT(M34^2+F33^2) -> 0.050990195 | M34: =IF(Imax<0.3, 0.12,0.05) -> 0.05
B37: dV/dT Capacitor and Output ramp Time(Tdvdt) Calculation
B38: Tdvdt_default | C38: Default Tdvdt with no external capacitor connected at dVdT pin | D38: =0.5*Vinmax/24 -> 0.75 | E38: ms
B39: Tdvdt_with_IINRUSH_permissible | C39: Tdvdt with IINRUSH_permissible | D39: =(Cout*10^-3*Vinmax)/(INRUSH) -> 90 | E39: ms
B40: Tdvdt required | C40: Enter Tdvdt if lower Tdvdt than the Tdvdt with IINRUSH_premissible is required | D40: 15 | E40: ms
B41: Cdvdt_for_permissible_IINRUSH | C41: Calculated dVdT capacitor value based on permissible Inrush current | D41: =MAX(((I_dvdt*Gain_dvdt*Cout*10^-6)/INRUSH),0.022) -> 0.12 | E41: µF | F41: =M41 -> 0.1 | M41: =IF(Cdvdt_cal1<=0.1,0.05,0.1) -> 0.1
B42: Cdvdt_for_required_Tdvdt | C42: Calculated dVdT capacitor value based on required Tdvdt | D42: =MAX(((Tdvdt_req*10^-3*Gain_dvdt*I_dvdt)/OVset),0.022) -> 0.022 | E42: µF | F42: 0.05 | M42: =IF(Cdvdt_cal2<=0.1,0.05,0.1) -> 0.05
B43: SELECT Cdvdt either for required Tdvdt or for Permissible IINRUSH
B44: Cdvdt | C44: Enter Selected value for CdV/dT capacitor | D44: =D41 -> 0.12 | E44: µF | F44: =F41 -> 0.1
...

Sheet Thermal Shutdown Limit Plot
A1: Thermal Shutdown Time (ms) Vs. Power Dissipation (W) | B1: RGE Package | H1: Title of Graph | J1: Thermal Shutdown Time Vs. Power Dissipation | Q1: RGE Package
A2: Power Dissipation (W) | B2: TA = -40C | C2: TA = 0C | D2: TA = 25C | E2: TA = 85C | F2: TA = 125C
A3: 3 | B3: 2740 | C3: 2740 | D3: 2740 | E3: 2740 | F3: 590 | H3: Lable | I3: X-Axis | J3: Power Dissipation (W)
A4: 6 | B4: 2740 | C4: 2740 | D4: 1920 | E4: 460 | F4: 77 | I4: Y-Axis | J4: Thermal Shutdown time (ms)
A5: 10 | B5: 2700 | C5: 960 | D5: 450 | E5: 95 | F5: 25
A6: 12.5 | B6: 1050 | C6: 520 | D6: 128 | E6: 63 | F6: 16
A7: 15 | B7: 590 | C7: 333 | D7: 93 | E7: 42 | F7: 8
A8: 20 | B8: 282 | C8: 160 | D8: 56 | E8: 22 | F8: 6.5
A9: 25 | B9: 155 | C9: 73 | D9: 40 | E9: 15 | F9: 4.5
A10: 30 | B10: 80 | C10: 51 | D10: 27.5 | E10: 9.4 | F10: 3.5
A11: 35 | B11: 58 | C11: 37 | D11: 23 | E11: 7 | F11: 2.8
A12: 40 | B12: 44 | C12: 28 | D12: 15.4 | E12: 5.5 | F12: 2.3
A13: 45 | B13: 34 | C13: 22 | D13: 11.5 | E13: 4.5 | F13: 2
A14: 50 | B14: 26 | C14: 17 | D14: 10 | E14: 3.8 | F14: 1.7
A15: 55 | B15: 21 | C15: 14 | D15: 8 | E15: 3.3 | F15: 1.5
A16: 60 | B16: 18 | C16: 11.4 | D16: 7 | E16: 2.9 | F16: 1.3
... A26: 360 | B26: 0.94 | C26: 0.75 | D26: 0.59 | E26: 0.33 | F26: 0.17
C33: Pd (W) | D33: Tstart-up (ms)
B34: Maximum Point | C34: ='Calculation Sheet'!D53 -> 15 | D34: =Tdvdt -> 90
B35: Operating Point | C35: ='Calculation Sheet'!D52 -> 11.72 | D35: =D34 -> 90
A39: Thermal Shutdown Time (ms) Vs. Power Dissipation (W) | B39: PWP Package | N39: PWP Package
A40: Power Dissipation (W) | B40: TA = -40C | C40: TA = 0C | D40: TA = 25C | E40: TA = 85C | F40: TA = 125C
A41: 3 | B41: 2733 | C41: 2733 | D41: 2733 | E41: 2733 | F41: 2733
A42: 6 | B42: 2733 | C42: 2733 | D42: 2700 | E42: 2328 | F42: 405.5
A43: 10 | B43: 2733 | C43: 2733 | D43: 1638.82 | E43: 413.52 | F43: 134.7
A44: 12.5 | B44: 2733 | C44: 1215.83 | D44: 784.93 | E44: 226.7 | F44: 78.378
A45: 15 | B45: 1368.86 | C45: 673.17 | D45: 459.33 | E45: 143.384 | F45: 50
A46: 20 | B46: 527.68 | C46: 298.09 | D46: 213.53 | E46: 71.962 | F46: 25.7
A47: 25 | B47: 285 | C47: 170.4 | D47: 123.95 | E47: 42.06 | F47: 15
A48: 30 | B48: 178.942 | C48: 108.95 | D48: 79.46 | E48: 27.352 | F48: 9.9
A49: 35 | B49: 118.69 | C49: 74.636 | D49: 54.73 | E49: 18.89 | F49: 6.87
A50: 40 | B50: 87.568 | C50: 55.32 | D50: 40.365 | E50: 13.7 | F50: 5.07
A51: 45 | B51: 65.22 | C51: 41.438 | D51: 30.63 | E51: 10.195 | F51: 4.04
A52: 50 | B52: 48.153 | C52: 31.543 | D52: 23.6 | E52: 7.88 | F52: 3.28
... A64: 360 | B64: 0.98 | C64: 0.851 | D64: 0.703 | E64: 0.458 | F64: 0.307
C67: Pd (W) | D67: Tstart-up (ms)
B68: Maximum Point | C68: ='Calculation Sheet'!D54 -> 25 | D68: =Tdvdt -> 90
B69: Operating Point | C69: ='Calculation Sheet'!D52 -> 11.72 | D69: =D68 -> 90

Sheet Res EIA Tables
A1: Standard EIA Decade Resistor Values
A3: 0.2 | B3: 0.1 | C3: 0.05 | D3: 0.02 | E3: 0.01 | F3: 0.5%, 0.25%, 0.1%
A4: E6 | B4: E12 | C4: E24 | D4: E48 | E4: E96 | F4: E192
A5: 100 | B5: 100 | C5: 100 | D5: 100 | E5: 100 | F5: 100
F6: 101
E7: 102 | F7: 102
F8: 104
D9: 105 | E9: 105 | F9: 105
F10: 106
E11: 107 | F11: 107
F12: 109
C13: 110 | D13: 110 | E13: 110 | F13: 110
F14: 111
E15: 113 | F15: 113
F16: 114
D17: 115 | E17: 115 | F17: 115
F18: 117
E19: 118 | F19: 118
F20: 120
B21: 120 | C21: 120 | D21: 121 | E21: 121 | F21: 121
F22: 123
E23: 124 | F23: 124
F24: 126
D25: 127 | E25: 127 | F25: 127
F26: 129
E27: 130 | F27: 130
F28: 132
C29: 130 | D29: 133 | E29: 133 | F29: 133
F30: 135
E31: 137 | F31: 137
F32: 138
D33: 140 | E33: 140 | F33: 140
F34: 142
E35: 143 | F35: 143
F36: 145
A37: 150 | B37: 150 | C37: 150 | D37: 147 | E37: 147 | F37: 147
F38: 149
E39: 150 | F39: 150
F40: 152
D41: 154 | E41: 154 | F41: 154
...

Sheet Cap Tables
A1: Capacitors Lookup Table
A2: µF
A3: 0.01
A4: 0.015
A5: 0.022
A6: 0.033
A7: 0.047
A8: 0.068
A9: 0.1
A10: 0.15
A11: 0.22
A12: 0.33
A13: 0.47
A14: 0.68
... A27: 100

Sheet Max_Cap_charging
B1: Temperture | C1: -40 C | D1: 0 C | E1: 25 C | F1: 105 C
A2: VIN (V)
A3: 4.5 | C3: 32mF | D3: 32mF | E3: 32mF | F3: 32mF
A4: 18 | C4: 32mF | D4: 32mF | E4: 32mF | F4: 32mF
A5: 32 | C5: 32mF | D5: 32mF | E5: 32mF | F5: 16mF
